{"uuid": "6ed49a19-794c-4ee1-a0a5-19abcc1e50a3", "children": ["c5e66d2f-d7fb-44a0-a68b-af3c814191b7"], "befores": [{"name": "_Class__pytest_setup_class", "status": "broken", "statusDetails": {"message": "selenium.common.exceptions.WebDriverException: Message: An unknown server-side error occurred while processing the command. Original error: Could not find a connected Android device.\n\n", "trace": "  File \"c:\\users\\admin\\appdata\\local\\programs\\python\\python36\\lib\\site-packages\\pluggy\\callers.py\", line 187, in _multicall\n    res = hook_impl.function(*args)\n  File \"c:\\users\\admin\\appdata\\local\\programs\\python\\python36\\lib\\site-packages\\_pytest\\fixtures.py\", line 927, in pytest_fixture_setup\n    result = call_fixture_func(fixturefunc, request, kwargs)\n  File \"c:\\users\\admin\\appdata\\local\\programs\\python\\python36\\lib\\site-packages\\_pytest\\fixtures.py\", line 774, in call_fixture_func\n    res = next(it)\n  File \"c:\\users\\admin\\appdata\\local\\programs\\python\\python36\\lib\\site-packages\\_pytest\\python.py\", line 730, in xunit_setup_class_fixture\n    _call_with_optional_argument(func, self.obj)\n  File \"c:\\users\\admin\\appdata\\local\\programs\\python\\python36\\lib\\site-packages\\_pytest\\python.py\", line 668, in _call_with_optional_argument\n    func(arg)\n  File \"E:\\pythoncode\\TPShop_App自动化项目\\script\\test_01_comment_system.py\", line 17, in setup_class\n  File \"E:\\0628软件测试\\18_APP项目\\20191011APP项目day_3\\项目汇报\\第一组\\TPShop_App自动化项目\\common\\base_app.py\", line 21, in open_app\n    return webdriver.Remote('http://127.0.0.1:4723/wd/hub', desired_caps)\n  File \"c:\\users\\admin\\appdata\\local\\programs\\python\\python36\\lib\\site-packages\\appium\\webdriver\\webdriver.py\", line 144, in __init__\n    proxy\n  File \"c:\\users\\admin\\appdata\\local\\programs\\python\\python36\\lib\\site-packages\\selenium\\webdriver\\remote\\webdriver.py\", line 157, in __init__\n    self.start_session(capabilities, browser_profile)\n  File \"c:\\users\\admin\\appdata\\local\\programs\\python\\python36\\lib\\site-packages\\appium\\webdriver\\webdriver.py\", line 219, in start_session\n    response = self.execute(RemoteCommand.NEW_SESSION, parameters)\n  File \"c:\\users\\admin\\appdata\\local\\programs\\python\\python36\\lib\\site-packages\\selenium\\webdriver\\remote\\webdriver.py\", line 321, in execute\n    self.error_handler.check_response(response)\n  File \"c:\\users\\admin\\appdata\\local\\programs\\python\\python36\\lib\\site-packages\\selenium\\webdriver\\remote\\errorhandler.py\", line 242, in check_response\n    raise exception_class(message, screen, stacktrace)\n"}, "start": 1570781937209, "stop": 1570781968629}], "start": 1570781937209, "stop": 1570781968811}